Workbook
Name Slicer_Category: #N/A
Name Slicer_Months__Date: #N/A

Sheet messy_expenses_1000
A1: S/N | B1: Date | C1: Description | D1: Category | E1: Amount
A2: 1 | B2: 45669 | C2: Miller-Sanchez | D2: Subscription | E2: 141
A3: 2 | B3: 45779 | C3: Lawrence, Rhodes And Cherry | D3: Food | E3: 124
A4: 3 | B4: 45373 | C4: Lee-Lester | D4: Coffee | E4: 174
A5: 4 | B5: 45953 | C5: Gibson-Wright | D5: Subscription | E5: 13
A6: 5 | B6: 45908 | C6: Espinoza-Chan | D6: Uncategorized | E6: 143
A7: 6 | B7: 45295 | C7: Anderson, Davis And Contreras | D7: Uncategorized | E7: 9
A8: 7 | B8: 45638 | C8: Unknown | D8: Shopping | E8: 64
A9: 8 | B9: 45378 | C9: Richardson Group | D9: Fitness | E9: 33
A10: 9 | B10: 46002 | C10: Contreras Ltd | D10: Shopping | E10: 102
A11: 10 | B11: 45488 | C11: Gardner Inc | D11: Food | E11: 147
A12: 11 | B12: 45336 | C12: Meza-Walton | D12: Uncategorized | E12: 92
A13: 12 | B13: 45978 | C13: Coleman Ltd | D13: Fitness | E13: 152
... A1001: 1000 | B1001: 45515 | C1001: Hansen Inc | D1001: Fitness | E1001: 163

Sheet Analysis
A3: Sum of Amount
A4: 98469
A6: Row Labels | B6: Sum of Amount
A7: Coffee | B7: 11658
A8: Fitness | B8: 10335
A9: Food | B9: 12245
A10: Shopping | B10: 11193
A11: Subscription | B11: 10388
A12: Transport | B12: 11128
A13: Uncategorized | B13: 22445
A14: Utilities | B14: 9077
A15: Grand Total | B15: 98469
A18: Row Labels | B18: Sum of Amount
A19: Jan | B19: 7271
A20: Feb | B20: 7802
A21: Mar | B21: 9269
A22: Apr | B22: 9784
A23: May | B23: 5933
A24: Jun | B24: 9068
A25: Jul | B25: 9751
A26: Aug | B26: 5675
A27: Sep | B27: 8841
A28: Oct | B28: 8850
A29: Nov | B29: 8898
A30: Dec | B30: 7327
A31: Grand Total | B31: 98469
A34: Row Labels | B34: Sum of Amount
A35: Coffee | B35: 11658
A36: Fitness | B36: 10335
A37: Food | B37: 12245
A38: Shopping | B38: 11193
A39: Subscription | B39: 10388
A40: Transport | B40: 11128
A41: Uncategorized | B41: 22445
A42: Utilities | B42: 9077
A43: Grand Total | B43: 98469
A59: Categories | P59: =A59 -> Categories | Q59: =B59 | R59: =C59 -> 0 | S59: =D59 -> 0 | T59: =E59 -> 0 | U59: =F59 -> 0 | V59: =G59 -> 0 | W59: =H59 -> 0 | ... AC59: =N59 -> 0
B60: Jan | C60: Feb | D60: Mar | E60: Apr | F60: May | G60: Jun | H60: Jul | I60: Aug | J60: Sep | K60: Oct | L60: Nov | M60: Dec | N60: Grand Total | P60: =A60 | Q60: =B60 -> Jan | R60: =C60 -> Feb | S60: =D60 -> Mar | T60: =E60 -> Apr | U60: =F60 -> May | V60: =G60 -> Jun | W60: =H60 -> Jul | ... AC60: =N60 -> Grand Total
A61: Coffee | B61: 681 | C61: 723 | D61: 1383 | E61: 790 | F61: 412 | G61: 636 | H61: 1131 | I61: 332 | J61: 1839 | K61: 837 | L61: 1388 | M61: 1506 | N61: 11658 | P61: =A61 -> Coffee | Q61: =B61 -> 681 | R61: =C61 -> 723 | S61: =D61 -> 1383 | T61: =E61 -> 790 | U61: =F61 -> 412 | V61: =G61 -> 636 | W61: =H61 -> 1131 | ... AC61: =N61 -> 11658
A62: Fitness | B62: 404 | C62: 366 | D62: 691 | E62: 789 | F62: 375 | G62: 1201 | H62: 1173 | I62: 827 | J62: 1025 | K62: 1032 | L62: 1605 | M62: 847 | N62: 10335 | P62: =A62 -> Fitness | Q62: =B62 -> 404 | R62: =C62 -> 366 | S62: =D62 -> 691 | T62: =E62 -> 789 | U62: =F62 -> 375 | V62: =G62 -> 1201 | W62: =H62 -> 1173 | ... AC62: =N62 -> 10335
...

Sheet cleaned_expenses_1000
A1: S/N | B1: Date | C1: Description | D1: Category | E1: Amount
A2: 1 | B2: 45669 | C2: Miller-Sanchez | D2: Subscription | E2: 141
A3: 2 | B3: 45779 | C3: Lawrence, Rhodes And Cherry | D3: Food | E3: 124
A4: 3 | B4: 45373 | C4: Lee-Lester | D4: Coffee | E4: 174
A5: 4 | B5: 45953 | C5: Gibson-Wright | D5: Subscription | E5: 13
A6: 5 | B6: 45908 | C6: Espinoza-Chan | D6: Uncategorized | E6: 143
A7: 6 | B7: 45295 | C7: Anderson, Davis And Contreras | D7: Uncategorized | E7: 9
A8: 7 | B8: 45638 | C8: Unknown | D8: Shopping | E8: 64
A9: 8 | B9: 45378 | C9: Richardson Group | D9: Fitness | E9: 33
A10: 9 | B10: 46002 | C10: Contreras Ltd | D10: Shopping | E10: 102
A11: 10 | B11: 45488 | C11: Gardner Inc | D11: Food | E11: 147
A12: 11 | B12: 45336 | C12: Meza-Walton | D12: Uncategorized | E12: 92
A13: 12 | B13: 45978 | C13: Coleman Ltd | D13: Fitness | E13: 152
... A1001: 1000 | B1001: 45515 | C1001: Hansen Inc | D1001: Fitness | E1001: 163

Sheet Dashboard 0.2
E20: Spending Heatmap
E21: =Analysis!A59 -> Categories
E22: =Analysis!A60 | F22: =Analysis!B60 -> Jan | G22: =Analysis!C60 -> Feb | H22: =Analysis!D60 -> Mar | I22: =Analysis!E60 -> Apr | J22: =Analysis!F60 -> May | K22: =Analysis!G60 -> Jun | L22: =Analysis!H60 -> Jul | ... R22: =Analysis!N60 -> Grand Total
E23: =Analysis!A61 -> Coffee | F23: =Analysis!B61 -> 681 | G23: =Analysis!C61 -> 723 | H23: =Analysis!D61 -> 1383 | I23: =Analysis!E61 -> 790 | J23: =Analysis!F61 -> 412 | K23: =Analysis!G61 -> 636 | L23: =Analysis!H61 -> 1131 | ... R23: =Analysis!N61 -> 11658
E24: =Analysis!A62 -> Fitness | F24: =Analysis!B62 -> 404 | G24: =Analysis!C62 -> 366 | H24: =Analysis!D62 -> 691 | I24: =Analysis!E62 -> 789 | J24: =Analysis!F62 -> 375 | K24: =Analysis!G62 -> 1201 | L24: =Analysis!H62 -> 1173 | ... R24: =Analysis!N62 -> 10335
E25: =Analysis!A63 -> Food | F25: =Analysis!B63 -> 995 | G25: =Analysis!C63 -> 1053 | H25: =Analysis!D63 -> 1117 | I25: =Analysis!E63 -> 1476 | J25: =Analysis!F63 -> 850 | K25: =Analysis!G63 -> 1008 | L25: =Analysis!H63 -> 1036 | ... R25: =Analysis!N63 -> 12245
E26: =Analysis!A64 -> Shopping | F26: =Analysis!B64 -> 835 | G26: =Analysis!C64 -> 848 | H26: =Analysis!D64 -> 562 | I26: =Analysis!E64 -> 1120 | J26: =Analysis!F64 -> 581 | K26: =Analysis!G64 -> 1316 | L26: =Analysis!H64 -> 1318 | ... R26: =Analysis!N64 -> 11193
E27: =Analysis!A65 -> Subscription | F27: =Analysis!B65 -> 1021 | G27: =Analysis!C65 -> 929 | H27: =Analysis!D65 -> 995 | I27: =Analysis!E65 -> 997 | J27: =Analysis!F65 -> 602 | K27: =Analysis!G65 -> 1255 | L27: =Analysis!H65 -> 1039 | ... R27: =Analysis!N65 -> 10388
E28: =Analysis!A66 -> Transport | F28: =Analysis!B66 -> 1128 | G28: =Analysis!C66 -> 851 | H28: =Analysis!D66 -> 1170 | I28: =Analysis!E66 -> 864 | J28: =Analysis!F66 -> 897 | K28: =Analysis!G66 -> 998 | L28: =Analysis!H66 -> 1080 | ... R28: =Analysis!N66 -> 11128
E29: =Analysis!A67 -> Uncategorized | F29: =Analysis!B67 -> 1347 | G29: =Analysis!C67 -> 2241 | H29: =Analysis!D67 -> 2818 | I29: =Analysis!E67 -> 2406 | J29: =Analysis!F67 -> 1653 | K29: =Analysis!G67 -> 1656 | L29: =Analysis!H67 -> 1943 | ... R29: =Analysis!N67 -> 22445
E30: =Analysis!A68 -> Utilities | F30: =Analysis!B68 -> 860 | G30: =Analysis!C68 -> 791 | H30: =Analysis!D68 -> 533 | I30: =Analysis!E68 -> 1342 | J30: =Analysis!F68 -> 563 | K30: =Analysis!G68 -> 998 | L30: =Analysis!H68 -> 1031 | ... R30: =Analysis!N68 -> 9077
E31: =Analysis!A69 -> Grand Total | F31: =Analysis!B69 -> 7271 | G31: =Analysis!C69 -> 7802 | H31: =Analysis!D69 -> 9269 | I31: =Analysis!E69 -> 9784 | J31: =Analysis!F69 -> 5933 | K31: =Analysis!G69 -> 9068 | L31: =Analysis!H69 -> 9751 | ... R31: =Analysis!N69 -> 98469
